{"uuid": "5492fe8b-42ec-4775-b942-36c22b5e1bcf", "children": ["fc1d134a-6d0c-4565-a115-11d0e48e6a95", "05bd2902-7635-4534-881a-5986c83fe301", "7e77710c-9169-43a1-a876-8fd7f70587e9", "3e158b04-0493-43c7-b7be-9680330454ce", "306ddbf4-741e-4092-a6b6-e6c28ec186b9", "bd288faa-7aec-4608-bcda-bc2d6adae391", "9f019a78-c408-4341-aaea-80e13df91d9f"], "befores": [{"name": "project_session_login", "status": "broken", "statusDetails": {"message": "FileNotFoundError: [Errno 2] No such file or directory: '../img/img_01.png'\n", "trace": "  File \"c:\\users\\user\\pycharmprojects\\pythonproject\\venv\\lib\\site-packages\\pluggy\\callers.py\", line 187, in _multicall\n    res = hook_impl.function(*args)\n  File \"c:\\users\\user\\pycharmprojects\\pythonproject\\venv\\lib\\site-packages\\_pytest\\fixtures.py\", line 1117, in pytest_fixture_setup\n    result = call_fixture_func(fixturefunc, request, kwargs)\n  File \"c:\\users\\user\\pycharmprojects\\pythonproject\\venv\\lib\\site-packages\\_pytest\\fixtures.py\", line 915, in call_fixture_func\n    fixture_result = next(generator)\n  File \"D:\\seleniumweb\\saas\\TestCase\\conftest.py\", line 38, in project_session_login\n    auth = Auth(driver).auth_all('../img/img_03.png')\n  File \"D:\\seleniumweb\\saas\\Common\\common_auth.py\", line 148, in auth_all\n    self.auth_img()\n  File \"D:\\seleniumweb\\saas\\Common\\common_auth.py\", line 25, in auth_img\n    img_save = Image.open('../img/img_01.png')\n  File \"c:\\users\\user\\pycharmprojects\\pythonproject\\venv\\lib\\site-packages\\PIL\\Image.py\", line 2878, in open\n    fp = builtins.open(filename, \"rb\")\n"}, "start": 1600675873399, "stop": 1600675885462}], "start": 1600675873399, "stop": 1600675886180}