{"uuid": "5f251b95-266e-4db1-8bbb-ad760be32499", "children": ["5931a5e0-c03c-4a3d-9346-0fb7ef661e19", "d4c98cbf-1cd9-4cae-9b09-cbabc9ff27e5", "f79b9cdf-f5f9-4cb7-93e7-4fe478981d85", "4e513ad1-296e-4ad1-a268-673f552bc0e8", "68bc923f-f7b5-4f2f-9c0e-da7e04676fe5", "c2b51253-0d69-49b2-b037-75ec0065c6a3", "0947ebad-2e60-445c-8391-6322552c6f4b"], "befores": [{"name": "start_module", "status": "broken", "statusDetails": {"message": "urllib3.exceptions.MaxRetryError: HTTPConnectionPool(host='127.0.0.1', port=9508): Max retries exceeded with url: /session/17afa61e715d3fe5e303a2ae0559dd38/timeouts (Caused by NewConnectionError('<urllib3.connection.HTTPConnection object at 0x0444D2F8>: Failed to establish a new connection: [WinError 10061] 由于目标计算机积极拒绝，无法连接。'))\n", "trace": "  File \"c:\\users\\user\\pycharmprojects\\pythonproject\\venv\\lib\\site-packages\\pluggy\\callers.py\", line 187, in _multicall\n    res = hook_impl.function(*args)\n  File \"c:\\users\\user\\pycharmprojects\\pythonproject\\venv\\lib\\site-packages\\_pytest\\fixtures.py\", line 1117, in pytest_fixture_setup\n    result = call_fixture_func(fixturefunc, request, kwargs)\n  File \"c:\\users\\user\\pycharmprojects\\pythonproject\\venv\\lib\\site-packages\\_pytest\\fixtures.py\", line 915, in call_fixture_func\n    fixture_result = next(generator)\n  File \"D:\\seleniumweb\\saas\\TestCase\\test_system\\conftest.py\", line 10, in start_module\n    driver.implicitly_wait(20)\n  File \"c:\\users\\user\\pycharmprojects\\pythonproject\\venv\\lib\\site-packages\\selenium\\webdriver\\remote\\webdriver.py\", line 911, in implicitly_wait\n    self.execute(Command.SET_TIMEOUTS, {\n  File \"c:\\users\\user\\pycharmprojects\\pythonproject\\venv\\lib\\site-packages\\selenium\\webdriver\\remote\\webdriver.py\", line 319, in execute\n    response = self.command_executor.execute(driver_command, params)\n  File \"c:\\users\\user\\pycharmprojects\\pythonproject\\venv\\lib\\site-packages\\selenium\\webdriver\\remote\\remote_connection.py\", line 374, in execute\n    return self._request(command_info[0], url, body=data)\n  File \"c:\\users\\user\\pycharmprojects\\pythonproject\\venv\\lib\\site-packages\\selenium\\webdriver\\remote\\remote_connection.py\", line 397, in _request\n    resp = self._conn.request(method, url, body=body, headers=headers)\n  File \"c:\\users\\user\\pycharmprojects\\pythonproject\\venv\\lib\\site-packages\\urllib3\\request.py\", line 79, in request\n    return self.request_encode_body(\n  File \"c:\\users\\user\\pycharmprojects\\pythonproject\\venv\\lib\\site-packages\\urllib3\\request.py\", line 171, in request_encode_body\n    return self.urlopen(method, url, **extra_kw)\n  File \"c:\\users\\user\\pycharmprojects\\pythonproject\\venv\\lib\\site-packages\\urllib3\\poolmanager.py\", line 336, in urlopen\n    response = conn.urlopen(method, u.request_uri, **kw)\n  File \"c:\\users\\user\\pycharmprojects\\pythonproject\\venv\\lib\\site-packages\\urllib3\\connectionpool.py\", line 754, in urlopen\n    return self.urlopen(\n  File \"c:\\users\\user\\pycharmprojects\\pythonproject\\venv\\lib\\site-packages\\urllib3\\connectionpool.py\", line 754, in urlopen\n    return self.urlopen(\n  File \"c:\\users\\user\\pycharmprojects\\pythonproject\\venv\\lib\\site-packages\\urllib3\\connectionpool.py\", line 754, in urlopen\n    return self.urlopen(\n  File \"c:\\users\\user\\pycharmprojects\\pythonproject\\venv\\lib\\site-packages\\urllib3\\connectionpool.py\", line 726, in urlopen\n    retries = retries.increment(\n  File \"c:\\users\\user\\pycharmprojects\\pythonproject\\venv\\lib\\site-packages\\urllib3\\util\\retry.py\", line 439, in increment\n    raise MaxRetryError(_pool, url, error or ResponseError(cause))\n"}, "start": 1600070886578, "stop": 1600070894586}], "start": 1600070886578, "stop": 1600070896673}